Workbook

Sheet Sheet1
A1: Tree | B1: Species | C1: Site | E1: Ring | F1: Ring Width | G1: Cell # (LW --> EW) | H1: Tracheid Length (pixels?) | M1: Graphing
D2: Year | H2: Line 1 | I2: Line 2 | J2: Line 3 | K2: Line 4 | L2: Line 5 | M2: Mean | N2: SD | O2: POS | P2: NEG | Q2: Mean (um) | R2: SD (um) | S2: POS (um) | T2: NEG (um) | X2: Max
A3: Above P1 -1 | B3: ES | C3: Cliff | D3: 2022 | E3: 1 | F3: 1208.954 | G3: 1 | H3: 3 | I3: 3.162 | J3: 4 | K3: 5 | L3: 6.325 | M3: =AVERAGE(H3:L3) -> 4.2974 | N3: =STDEV(H3:L3) -> 1.3843442 | O3: =M3+N3 -> 5.6817442 | P3: =M3-N3 -> 2.9130558 | Q3: =M3/1.325 -> 3.2433208 | R3: =N3/1.325 -> 1.0447881 | S3: =Q3+R3 -> 4.2881088 | T3: =Q3-R3 -> 2.1985327 | U3: 1 | V3: =F3/1.325 -> 912.41811
A4: Above P1 -1 | B4: ES | C4: Cliff | E4: 1 | G4: 2 | H4: 3 | I4: 6 | J4: 5 | K4: 4.123 | L4: 6.325 | M4: =AVERAGE(H4:L4) -> 4.8896 | N4: =STDEV(H4:L4) -> 1.365999 | O4: =M4+N4 -> 6.255599 | P4: =M4-N4 -> 3.523601 | Q4: =M4/1.325 -> 3.6902642 | R4: =N4/1.325 -> 1.0309427 | S4: =Q4+R4 -> 4.7212068 | T4: =Q4-R4 -> 2.6593215 | U4: 2 | V4: =F45/1.325 -> 912.96679
A5: Above P1 -1 | B5: ES | C5: Cliff | E5: 1 | G5: 3 | H5: 3.162 | I5: 3 | J5: 4 | K5: 7.28 | L5: 9.055 | M5: =AVERAGE(H5:L5) -> 5.2994 | N5: =STDEV(H5:L5) -> 2.7189827 | O5: =M5+N5 -> 8.0183827 | P5: =M5-N5 -> 2.5804173 | Q5: =M5/1.325 -> 3.9995472 | R5: =N5/1.325 -> 2.0520624 | S5: =Q5+R5 -> 6.0516096 | T5: =Q5-R5 -> 1.9474848 | U5: 3 | V5: =F86/1.325 -> 575.53811
A6: Above P1 -1 | B6: ES | C6: Cliff | E6: 1 | G6: 4 | H6: 1 | I6: 5.099 | J6: 5.099 | K6: 8.062 | L6: 8.246 | M6: =AVERAGE(H6:L6) -> 5.5012 | N6: =STDEV(H6:L6) -> 2.9443146 | O6: =M6+N6 -> 8.4455146 | P6: =M6-N6 -> 2.5568854 | Q6: =M6/1.325 -> 4.1518491 | R6: =N6/1.325 -> 2.2221243 | S6: =Q6+R6 -> 6.3739733 | T6: =Q6-R6 -> 1.9297248 | U6: 4 | V6: =F112/1.325 -> 723.35019
A7: Above P1 -1 | B7: ES | C7: Cliff | E7: 1 | G7: 5 | H7: 7.071 | I7: 5 | J7: 7.28 | K7: 6.083 | L7: 7.28 | M7: =AVERAGE(H7:L7) -> 6.5428 | N7: =STDEV(H7:L7) -> 0.99468221 | O7: =M7+N7 -> 7.5374822 | P7: =M7-N7 -> 5.5481178 | Q7: =M7/1.325 -> 4.9379623 | R7: =N7/1.325 -> 0.75070356 | S7: =Q7+R7 -> 5.6886658 | T7: =Q7-R7 -> 4.1872587 | U7: 5 | V7: =F148/1.325 -> 914.2717
A8: Above P1 -1 | B8: ES | C8: Cliff | E8: 1 | G8: 5 | H8: 6.083 | I8: 6.083 | J8: 6.325 | K8: 7.071 | L8: 6.083 | M8: =AVERAGE(H8:L8) -> 6.329 | N8: =STDEV(H8:L8) -> 0.42782239 | O8: =M8+N8 -> 6.7568224 | P8: =M8-N8 -> 5.9011776 | Q8: =M8/1.325 -> 4.7766038 | R8: =N8/1.325 -> 0.32288482 | S8: =Q8+R8 -> 5.0994886 | T8: =Q8-R8 -> 4.4537189
A9: Above P1 -1 | B9: ES | C9: Cliff | E9: 1 | G9: 6 | H9: 3 | I9: 7.28 | J9: 6 | K9: 6.083 | L9: 8.246 | M9: =AVERAGE(H9:L9) -> 6.1218 | N9: =STDEV(H9:L9) -> 1.9758308 | O9: =M9+N9 -> 8.0976308 | P9: =M9-N9 -> 4.1459692 | Q9: =M9/1.325 -> 4.6202264 | R9: =N9/1.325 -> 1.491193 | S9: =Q9+R9 -> 6.1114194 | T9: =Q9-R9 -> 3.1290334
A10: Above P1 -1 | B10: ES | C10: Cliff | E10: 1 | G10: 7 | H10: 11.402 | I10: 7.616 | J10: 7.071 | K10: 11.402 | L10: 9.055 | M10: =AVERAGE(H10:L10) -> 9.3092 | N10: =STDEV(H10:L10) -> 2.0433249 | O10: =M10+N10 -> 11.352525 | P10: =M10-N10 -> 7.2658751 | Q10: =M10/1.325 -> 7.0258113 | R10: =N10/1.325 -> 1.542132 | S10: =Q10+R10 -> 8.5679433 | T10: =Q10-R10 -> 5.4836793
A11: Above P1 -1 | B11: ES | C11: Cliff | E11: 1 | G11: 8 | H11: 10 | I11: 9 | J11: 10.198 | K11: 11.402 | L11: 11.402 | M11: =AVERAGE(H11:L11) -> 10.4004 | N11: =STDEV(H11:L11) -> 1.0208833 | O11: =M11+N11 -> 11.421283 | P11: =M11-N11 -> 9.3795167 | Q11: =M11/1.325 -> 7.8493585 | R11: =N11/1.325 -> 0.77047799 | S11: =Q11+R11 -> 8.6198365 | T11: =Q11-R11 -> 7.0788805
A12: Above P1 -1 | B12: ES | C12: Cliff | E12: 1 | G12: 10 | H12: 10.05 | I12: 12.649 | J12: 13.342 | K12: 18.974 | L12: 16.763 | M12: =AVERAGE(H12:L12) -> 14.3556 | N12: =STDEV(H12:L12) -> 3.5214789 | O12: =M12+N12 -> 17.877079 | P12: =M12-N12 -> 10.834121 | Q12: =M12/1.325 -> 10.834415 | R12: =N12/1.325 -> 2.6577199 | S12: =Q12+R12 -> 13.492135 | T12: =Q12-R12 -> 8.1766952
A13: Above P1 -1 | B13: ES | C13: Cliff | E13: 1 | G13: 11 | H13: 19.416 | I13: 10.05 | J13: 11.045 | K13: 17.088 | L13: 19.647 | M13: =AVERAGE(H13:L13) -> 15.4492 | N13: =STDEV(H13:L13) -> 4.5986691 | O13: =M13+N13 -> 20.047869 | P13: =M13-N13 -> 10.850531 | Q13: =M13/1.325 -> 11.659774 | R13: =N13/1.325 -> 3.4706937 | S13: =Q13+R13 -> 15.130467 | T13: =Q13-R13 -> 8.1890799
A14: Above P1 -1 | B14: ES | C14: Cliff | E14: 1 | G14: 12 | H14: 13.342 | I14: 10.77 | J14: 8.544 | K14: 11.705 | L14: 18.028 | M14: =AVERAGE(H14:L14) -> 12.4778 | N14: =STDEV(H14:L14) -> 3.5545796 | O14: =M14+N14 -> 16.03238 | P14: =M14-N14 -> 8.9232204 | Q14: =M14/1.325 -> 9.4172075 | R14: =N14/1.325 -> 2.6827016 | S14: =Q14+R14 -> 12.099909 | T14: =Q14-R14 -> 6.734506
A15: Above P1 -1 | B15: ES | C15: Cliff | E15: 1 | G15: 13 | H15: 20.881 | I15: 19.416 | J15: 14.036 | K15: 14.56 | L15: 16.492 | M15: =AVERAGE(H15:L15) -> 17.077 | N15: =STDEV(H15:L15) -> 2.9944337 | O15: =M15+N15 -> 20.071434 | P15: =M15-N15 -> 14.082566 | Q15: =M15/1.325 -> 12.888302 | R15: =N15/1.325 -> 2.2599499 | S15: =Q15+R15 -> 15.148252 | T15: =Q15-R15 -> 10.628352
A16: Above P1 -1 | B16: ES | C16: Cliff | E16: 1 | G16: 14 | H16: 17.263 | I16: 19.925 | J16: 15.524 | K16: 16.763 | L16: 15.524 | M16: =AVERAGE(H16:L16) -> 16.9998 | N16: =STDEV(H16:L16) -> 1.8054165 | O16: =M16+N16 -> 18.805216 | P16: =M16-N16 -> 15.194384 | Q16: =M16/1.325 -> 12.830038 | R16: =N16/1.325 -> 1.3625785 | S16: =Q16+R16 -> 14.192616 | T16: =Q16-R16 -> 11.467459
A17: Above P1 -1 | B17: ES | C17: Cliff | E17: 1 | G17: 15 | H17: 12.369 | I17: 17.72 | J17: 23.77 | K17: 22.804 | L17: 23.087 | M17: =AVERAGE(H17:L17) -> 19.95 | N17: =STDEV(H17:L17) -> 4.8739857 | O17: =M17+N17 -> 24.823986 | P17: =M17-N17 -> 15.076014 | Q17: =M17/1.325 -> 15.056604 | R17: =N17/1.325 -> 3.6784798 | S17: =Q17+R17 -> 18.735084 | T17: =Q17-R17 -> 11.378124
A18: Above P1 -1 | B18: ES | C18: Cliff | E18: 1 | G18: 16 | H18: 16.031 | I18: 21.84 | J18: 25 | K18: 22.472 | L18: 28.792 | M18: =AVERAGE(H18:L18) -> 22.827 | N18: =STDEV(H18:L18) -> 4.6794488 | O18: =M18+N18 -> 27.506449 | P18: =M18-N18 -> 18.147551 | Q18: =M18/1.325 -> 17.227925 | R18: =N18/1.325 -> 3.5316595 | S18: =Q18+R18 -> 20.759584 | T18: =Q18-R18 -> 13.696265
A19: Above P1 -1 | B19: ES | C19: Cliff | E19: 1 | G19: 17 | H19: 22.561 | I19: 21.587 | J19: 21.19 | K19: 21.541 | L19: 23.345 | M19: =AVERAGE(H19:L19) -> 22.0448 | N19: =STDEV(H19:L19) -> 0.88756138 | O19: =M19+N19 -> 22.932361 | P19: =M19-N19 -> 21.157239 | Q19: =M19/1.325 -> 16.637585 | R19: =N19/1.325 -> 0.66985764 | S19: =Q19+R19 -> 17.307443 | T19: =Q19-R19 -> 15.967727
... A40: Above P1 -1 | B40: ES | C40: Cliff | E40: 1 | G40: 38 | H40: 34.482 | I40: 34.713 | J40: 32.558 | K40: 28.792 | L40: 9.487 | M40: =AVERAGE(H40:L40) -> 28.0064 | N40: =STDEV(H40:L40) -> 10.620903 | O40: =M40+N40 -> 38.627303 | P40: =M40-N40 -> 17.385497 | Q40: =M40/1.325 -> 21.136906 | R40: =N40/1.325 -> 8.0157755 | S40: =Q40+R40 -> 29.152681 | T40: =Q40-R40 -> 13.12113
A41: Above P1 -1 | B41: ES | C41: Cliff | E41: 1 | G41: 39 | H41: 24.739 | I41: 30.806 | J41: 26.077 | K41: 36.688 | L41: NA | M41: =AVERAGE(H41:L41) -> 29.5775 | N41: =STDEV(H41:L41) -> 5.4078032 | O41: =M41+N41 -> 34.985303 | P41: =M41-N41 -> 24.169697 | Q41: =M41/1.325 -> 22.322642 | R41: =N41/1.325 -> 4.0813609 | S41: =Q41+R41 -> 26.404002 | T41: =Q41-R41 -> 18.241281
A42: Above P1 -1 | B42: ES | C42: Cliff | E42: 1 | G42: 40 | H42: 32.016 | I42: 25.298 | J42: 24.739 | K42: 27.203 | L42: NA | M42: =AVERAGE(H42:L42) -> 27.314 | N42: =STDEV(H42:L42) -> 3.3073658 | O42: =M42+N42 -> 30.621366 | P42: =M42-N42 -> 24.006634 | Q42: =M42/1.325 -> 20.61434 | R42: =N42/1.325 -> 2.4961251 | S42: =Q42+R42 -> 23.110465 | T42: =Q42-R42 -> 18.118214
A43: Above P1 -1 | B43: ES | C43: Cliff | E43: 1 | G43: 41 | H43: 28.443 | I43: 31.78 | J43: 35.511 | K43: 28.16 | L43: NA | M43: =AVERAGE(H43:L43) -> 30.9735 | N43: =STDEV(H43:L43) -> 3.4427974 | O43: =M43+N43 -> 34.416297 | P43: =M43-N43 -> 27.530703 | Q43: =M43/1.325 -> 23.376226 | R43: =N43/1.325 -> 2.5983376 | S43: =Q43+R43 -> 25.974564 | T43: =Q43-R43 -> 20.777889
A44: Above P1 -1 | B44: ES | C44: Cliff | E44: 1 | G44: 42 | H44: 11.402 | I44: 12.369 | J44: 20.1 | K44: 32.28 | L44: NA | M44: =AVERAGE(H44:L44) -> 19.03775 | N44: =STDEV(H44:L44) -> 9.6481857 | O44: =M44+N44 -> 28.685936 | P44: =M44-N44 -> 9.3895643 | Q44: =M44/1.325 -> 14.368113 | R44: =N44/1.325 -> 7.2816496 | S44: =Q44+R44 -> 21.649763 | T44: =Q44-R44 -> 7.0864636
A45: Above P1 -1 | B45: ES | C45: Cliff | D45: 2021 | E45: 2 | F45: 1209.681 | G45: 1 | H45: 5.852 | I45: 4.743 | J45: 6.021 | K45: 5.523 | L45: 3.536 | M45: =AVERAGE(H45:L45) -> 5.135 | N45: =STDEV(H45:L45) -> 1.0198154 | O45: =M45+N45 -> 6.1548154 | P45: =M45-N45 -> 4.1151846 | Q45: =M45/1.325 -> 3.8754717 | R45: =N45/1.325 -> 0.76967202 | S45: =Q45+R45 -> 4.6451437 | T45: =Q45-R45 -> 3.1057997
A46: Above P1 -1 | B46: ES | C46: Cliff | E46: 2 | G46: 2 | H46: 4.743 | I46: 4.123 | J46: 4.61 | K46: 7 | L46: 4.5 | M46: =AVERAGE(H46:L46) -> 4.9952 | N46: =STDEV(H46:L46) -> 1.1442424 | O46: =M46+N46 -> 6.1394424 | P46: =M46-N46 -> 3.8509576 | Q46: =M46/1.325 -> 3.7699623 | R46: =N46/1.325 -> 0.86357918 | S46: =Q46+R46 -> 4.6335414 | T46: =Q46-R46 -> 2.9063831
A47: Above P1 -1 | B47: ES | C47: Cliff | E47: 2 | G47: 3 | H47: 6.801 | I47: 6.5 | J47: 4.743 | K47: 9.014 | L47: 4.743 | M47: =AVERAGE(H47:L47) -> 6.3602 | N47: =STDEV(H47:L47) -> 1.7668598 | O47: =M47+N47 -> 8.1270598 | P47: =M47-N47 -> 4.5933402 | Q47: =M47/1.325 -> 4.8001509 | R47: =N47/1.325 -> 1.3334791 | S47: =Q47+R47 -> 6.1336301 | T47: =Q47-R47 -> 3.4666718
A48: Above P1 -1 | B48: ES | C48: Cliff | E48: 2 | G48: 4 | H48: 12.166 | I48: 7.566 | J48: 5.22 | K48: 6.576 | L48: 7 | M48: =AVERAGE(H48:L48) -> 7.7056 | N48: =STDEV(H48:L48) -> 2.6394474 | O48: =M48+N48 -> 10.345047 | P48: =M48-N48 -> 5.0661526 | Q48: =M48/1.325 -> 5.8155472 | R48: =N48/1.325 -> 1.9920358 | S48: =Q48+R48 -> 7.807583 | T48: =Q48-R48 -> 3.8235114
A49: Above P1 -1 | B49: ES | C49: Cliff | E49: 2 | G49: 5 | H49: 16.492 | I49: 9.487 | J49: 6.325 | K49: 9.513 | L49: 11.673 | M49: =AVERAGE(H49:L49) -> 10.698 | N49: =STDEV(H49:L49) -> 3.7588208 | O49: =M49+N49 -> 14.456821 | P49: =M49-N49 -> 6.9391792 | Q49: =M49/1.325 -> 8.0739623 | R49: =N49/1.325 -> 2.8368459 | S49: =Q49+R49 -> 10.910808 | T49: =Q49-R49 -> 5.2371164
A50: Above P1 -1 | B50: ES | C50: Cliff | E50: 2 | G50: 6 | H50: 11.673 | I50: 7.018 | J50: 11.673 | K50: 16.568 | L50: 17.029 | M50: =AVERAGE(H50:L50) -> 12.7922 | N50: =STDEV(H50:L50) -> 4.1247346 | O50: =M50+N50 -> 16.916935 | P50: =M50-N50 -> 8.6674654 | Q50: =M50/1.325 -> 9.6544906 | R50: =N50/1.325 -> 3.1130073 | S50: =Q50+R50 -> 12.767498 | T50: =Q50-R50 -> 6.5414833
A51: Above P1 -1 | B51: ES | C51: Cliff | E51: 2 | G51: 7 | H51: 12.981 | I51: 16.492 | J51: 9.014 | K51: 12.855 | L51: 18.828 | M51: =AVERAGE(H51:L51) -> 14.034 | N51: =STDEV(H51:L51) -> 3.7657486 | O51: =M51+N51 -> 17.799749 | P51: =M51-N51 -> 10.268251 | Q51: =M51/1.325 -> 10.591698 | R51: =N51/1.325 -> 2.8420744 | S51: =Q51+R51 -> 13.433773 | T51: =Q51-R51 -> 7.7496237
A52: Above P1 -1 | B52: ES | C52: Cliff | E52: 2 | G52: 8 | H52: 8.078 | I52: 8.5 | J52: 7.762 | K52: 15.628 | L52: 18.248 | M52: =AVERAGE(H52:L52) -> 11.6432 | N52: =STDEV(H52:L52) -> 4.9283893 | O52: =M52+N52 -> 16.571589 | P52: =M52-N52 -> 6.7148107 | Q52: =M52/1.325 -> 8.7873208 | R52: =N52/1.325 -> 3.7195391 | S52: =Q52+R52 -> 12.50686 | T52: =Q52-R52 -> 5.0677817
A53: Above P1 -1 | B53: ES | C53: Cliff | E53: 2 | G53: 9 | H53: 9.055 | I53: 11.18 | J53: 13.829 | K53: 14.577 | L53: 16.771 | M53: =AVERAGE(H53:L53) -> 13.0824 | N53: =STDEV(H53:L53) -> 3.0098209 | O53: =M53+N53 -> 16.092221 | P53: =M53-N53 -> 10.072579 | Q53: =M53/1.325 -> 9.8735094 | R53: =N53/1.325 -> 2.2715629 | S53: =Q53+R53 -> 12.145072 | T53: =Q53-R53 -> 7.6019465
A54: Above P1 -1 | B54: ES | C54: Cliff | E54: 2 | G54: 10 | H54: 14.714 | I54: 12.748 | J54: 8.515 | K54: 12.649 | L54: 23.838 | M54: =AVERAGE(H54:L54) -> 14.4928 | N54: =STDEV(H54:L54) -> 5.691215 | O54: =M54+N54 -> 20.184015 | P54: =M54-N54 -> 8.801585 | Q54: =M54/1.325 -> 10.937962 | R54: =N54/1.325 -> 4.2952566 | S54: =Q54+R54 -> 15.233219 | T54: =Q54-R54 -> 6.6427057
A55: Above P1 -1 | B55: ES | C55: Cliff | E55: 2 | G55: 11 | H55: 17.507 | I55: 13.601 | J55: 8.139 | K55: 12.649 | L55: 11.281 | M55: =AVERAGE(H55:L55) -> 12.6354 | N55: =STDEV(H55:L55) -> 3.4174942 | O55: =M55+N55 -> 16.052894 | P55: =M55-N55 -> 9.2179058 | Q55: =M55/1.325 -> 9.5361509 | R55: =N55/1.325 -> 2.5792409 | S55: =Q55+R55 -> 12.115392 | T55: =Q55-R55 -> 6.95691
A56: Above P1 -1 | B56: ES | C56: Cliff | E56: 2 | G56: 12 | H56: 20.012 | I56: 10.689 | J56: 14.318 | K56: 10.689 | L56: 6.519 | M56: =AVERAGE(H56:L56) -> 12.4454 | N56: =STDEV(H56:L56) -> 5.0510436 | O56: =M56+N56 -> 17.496444 | P56: =M56-N56 -> 7.3943564 | Q56: =M56/1.325 -> 9.3927547 | R56: =N56/1.325 -> 3.8121084 | S56: =Q56+R56 -> 13.204863 | T56: =Q56-R56 -> 5.5806464
A57: Above P1 -1 | B57: ES | C57: Cliff | E57: 2 | G57: 13 | H57: 27.286 | I57: 17.263 | J57: 8.246 | K57: 15.572 | L57: 9.487 | M57: =AVERAGE(H57:L57) -> 15.5708 | N57: =STDEV(H57:L57) -> 7.5956364 | O57: =M57+N57 -> 23.166436 | P57: =M57-N57 -> 7.9751636 | Q57: =M57/1.325 -> 11.751547 | R57: =N57/1.325 -> 5.7325558 | S57: =Q57+R57 -> 17.484103 | T57: =Q57-R57 -> 6.0189914
... A82: Above P1 -1 | B82: ES | C82: Cliff | E82: 2 | G82: 38 | H82: 28.518 | I82: 31.977 | J82: 27.171 | K82: 18 | L82: 30.594 | M82: =AVERAGE(H82:L82) -> 27.252 | N82: =STDEV(H82:L82) -> 5.4932552 | O82: =M82+N82 -> 32.745255 | P82: =M82-N82 -> 21.758745 | Q82: =M82/1.325 -> 20.567547 | R82: =N82/1.325 -> 4.145853 | S82: =Q82+R82 -> 24.7134 | T82: =Q82-R82 -> 16.421694
A83: Above P1 -1 | B83: ES | C83: Cliff | E83: 2 | G83: 39 | H83: 25.831 | I83: 33.801 | J83: 31.085 | K83: 36.062 | L83: NA | M83: =AVERAGE(H83:L83) -> 31.69475 | N83: =STDEV(H83:L83) -> 4.4069839 | O83: =M83+N83 -> 36.101734 | P83: =M83-N83 -> 27.287766 | Q83: =M83/1.325 -> 23.920566 | R83: =N83/1.325 -> 3.3260256 | S83: =Q83+R83 -> 27.246592 | T83: =Q83-R83 -> 20.59454
A84: Above P1 -1 | B84: ES | C84: Cliff | E84: 2 | G84: 40 | H84: 25.676 | I84: 22.023 | J84: 24.91 | K84: NA | L84: NA | M84: =AVERAGE(H84:L84) -> 24.203 | N84: =STDEV(H84:L84) -> 1.9263927 | O84: =M84+N84 -> 26.129393 | P84: =M84-N84 -> 22.276607 | Q84: =M84/1.325 -> 18.266415 | R84: =N84/1.325 -> 1.4538813 | S84: =Q84+R84 -> 19.720296 | T84: =Q84-R84 -> 16.812534
...

Sheet Standardized - 2018
A1: Year | B1: Standardized Cell Number | C1: Under42 | D1: WAS27 | E1: WAS03 | F1: WAS21 | G1: WAS36 | H1: WAS49 | I1: GT-1 | J1: GT-3 | K1: GT-4 | L1: WAS61 | M1: AboveP1 | N1: WAS51 | O1: WAS50 | P1: WAS42 | Q1: WAS01 | R1: WAS04 | S1: WAS63 | T1: WAS64 | U1: WAS48 | V1: WAS57 | W1: WAS65 | Y1: Standardized Ring | Z1: DF-Cliff | AA1: DF-Soil | AB1: ES-Cliff | AC1: ES-Soil | AD1: DF-Cliff_ERROR | AE1: DF-Soil_ERROR | AF1: ES-Cliff_ERROR | AG1: ES-Soil_ERROR | AI1: Species | AJ1: Site | AK1: Average LD | AL1: SD | AM1: SE
A2: 2018 | B2: 1 | C2: 2.8813333 | D2: 2.264 | E2: 3.1804802 | F2: 1.36525 | G2: 2.5685385 | H2: 2.2181228 | I2: 3.1395 | J2: 2.735875 | K2: 9.07275 | L2: 2.438194 | M2: 3.2400037 | N2: 3.5213585 | O2: 2.5156667 | P2: 1.8865 | Q2: 3.05 | R2: 4.3035 | S2: 4.0356458 | T2: 3.1541538 | U2: 2.8973814 | V2: 2.4638529 | W2: 3.9176232 | Y2: 1 | Z2: =AVERAGE(C2:G2) -> 2.4519204 | AA2: =AVERAGE(H2:L2) -> 3.9208884 | AB2: =AVERAGE(M2:R2) -> 3.0861715 | AC2: =AVERAGE(S2:W2) -> 3.2937314 | AD2: =STDEV($C2:$G2) -> 0.69730933 | AE2: =STDEV($H2:$L2) -> 2.9006161 | AF2: =STDEV($M2:$R2) -> 0.83197795 | AG2: =STDEV($S2:$W2) -> 0.67174242 | AI2: Spruce | AJ2: Soil | AK2: =AVERAGE(S2:W26) -> 23.025567 | AL2: =STDEV(S2:W26) -> 9.849947 | AM2: =AL2/SQRT(125) -> 0.88100605
A3: 2018 | B3: 2 | C3: 3.6031754 | D3: 2.264 | E3: 5.2665516 | F3: 1.4769464 | G3: 4.3682821 | H3: 3.5970906 | I3: 4.2296042 | J3: 5.5831667 | K3: 8.06475 | L3: 3.1595448 | M3: 4.5842025 | N3: 3.6055849 | O3: 2.7330152 | P3: 3.5325965 | Q3: 3.05 | R3: 4.3196875 | S3: 5.9042292 | T3: 4.2991538 | U3: 5.2317966 | V3: 5.5160588 | W3: 7.3835797 | Y3: 2 | Z3: =AVERAGE(C3:G3) -> 3.3957911 | AA3: =AVERAGE(H3:L3) -> 4.9268313 | AB3: =AVERAGE(M3:R3) -> 3.6375144 | AC3: =AVERAGE(S3:W3) -> 5.6669636 | AD3: =STDEV($C3:$G3) -> 1.5371571 | AE3: =STDEV($H3:$L3) -> 1.9783167 | AF3: =STDEV($M3:$R3) -> 0.7123058 | AG3: =STDEV($S3:$W3) -> 1.1276205 | AI3: Spruce | AJ3: Cliff | AK3: =AVERAGE(M2:Q26) -> 15.341354 | AL3: =STDEV(M2:Q26) -> 7.5335678 | AM3: =AL3/SQRT(125) -> 0.67382279
A4: 2018 | B4: 3 | C4: 4.1636184 | D4: 2.264 | E4: 6.2294127 | F4: 1.8865 | G4: 5.7072051 | H4: 3.9569064 | I4: 4.7885 | J4: 7.8398333 | K4: 7.0295 | L4: 2.6478284 | M4: 5.4251413 | N4: 3.7740377 | O4: 2.7673333 | P4: 4.2942982 | Q4: 3.05 | R4: 4.3405 | S4: 7.1297083 | T4: 7.0143846 | U4: 8.713113 | V4: 6.5036618 | W4: 9.9284203 | Y4: 3 | Z4: =AVERAGE(C4:G4) -> 4.0501472 | AA4: =AVERAGE(H4:L4) -> 5.2525136 | AB4: =AVERAGE(M4:R4) -> 3.9418851 | AC4: =AVERAGE(S4:W4) -> 7.8578576 | AD4: =STDEV($C4:$G4) -> 1.960842 | AE4: =STDEV($H4:$L4) -> 2.1523357 | AF4: =STDEV($M4:$R4) -> 0.96812617 | AG4: =STDEV($S4:$W4) -> 1.4225142 | AI4: Douglas Fir | AJ4: Soil | AK4: =AVERAGE(H2:L26) -> 18.020608 | AL4: =STDEV(H2:L26) -> 11.000374 | AM4: =AL4/SQRT(125) -> 0.98390339
A5: 2018 | B5: 4 | C5: 4.5628816 | D5: 3.0752857 | E5: 5.4809048 | F5: 3.3471786 | G5: 4.0327436 | H5: 5.6324693 | I5: 4.8084583 | J5: 9.84375 | K5: 6.58425 | L5: 3.2752463 | M5: 6.4966737 | N5: 4.8701887 | O5: 3.6594091 | P5: 4.3538246 | Q5: 3.0226563 | R5: 6.3166875 | S5: 7.4373403 | T5: 8.0630769 | U5: 14.694938 | V5: 9.4448676 | W5: 12.983217 | Y5: 4 | Z5: =AVERAGE(C5:G5) -> 4.0997988 | AA5: =AVERAGE(H5:L5) -> 6.0288348 | AB5: =AVERAGE(M5:R5) -> 4.7865733 | AC5: =AVERAGE(S5:W5) -> 10.524688 | AD5: =STDEV($C5:$G5) -> 0.96727194 | AE5: =STDEV($H5:$L5) -> 2.4541158 | AF5: =STDEV($M5:$R5) -> 1.4029867 | AG5: =STDEV($S5:$W5) -> 3.169882 | AI5: Douglas Fir | AJ5: Cliff | AK5: =AVERAGE(C2:G26) -> 14.319844 | AL5: =STDEV(C2:G26) -> 8.3036084 | AM5: =AL5/SQRT(125) -> 0.74269731
A6: 2018 | B6: 5 | C6: 4.73625 | D6: 4.157 | E6: 6.163623 | F6: 5.29475 | G6: 4.7473333 | H6: 6.0641974 | I6: 5.8552222 | J6: 11.563833 | K6: 6.50025 | L6: 3.5573582 | M6: 7.6638638 | N6: 5.4182642 | O6: 4.5056364 | P6: 5.3646667 | Q6: 3.01875 | R6: 6.7188958 | S6: 7.8239792 | T6: 10.229103 | U6: 18.978774 | V6: 15.057956 | W6: 12.795952 | Y6: 5 | Z6: =AVERAGE(C6:G6) -> 5.0197913 | AA6: =AVERAGE(H6:L6) -> 6.7081722 | AB6: =AVERAGE(M6:R6) -> 5.4483461 | AC6: =AVERAGE(S6:W6) -> 12.977153 | AD6: =STDEV($C6:$G6) -> 0.75547851 | AE6: =STDEV($H6:$L6) -> 2.9449335 | AF6: =STDEV($M6:$R6) -> 1.6323211 | AG6: =STDEV($S6:$W6) -> 4.3153508
A7: 2018 | B7: 6 | C7: 5.1341079 | D7: 4.157 | E7: 5.7449921 | F7: 6.6214464 | G7: 4.3443333 | H7: 6.4943684 | I7: 7.1343472 | J7: 12.982375 | K7: 5.87025 | L7: 4.8162313 | M7: 10.27863 | N7: 9.9062642 | O7: 5.3402121 | P7: 5.6905965 | Q7: 3.01875 | R7: 6.9826667 | S7: 13.373056 | T7: 17.146628 | U7: 20.328028 | V7: 10.730971 | W7: 13.7893 | Y7: 6 | Z7: =AVERAGE(C7:G7) -> 5.2003759 | AA7: =AVERAGE(H7:L7) -> 7.4595144 | AB7: =AVERAGE(M7:R7) -> 6.86952 | AC7: =AVERAGE(S7:W7) -> 15.073596 | AD7: =STDEV($C7:$G7) -> 1.0175807 | AE7: =STDEV($H7:$L7) -> 3.2035892 | AF7: =STDEV($M7:$R7) -> 2.8076226 | AG7: =STDEV($S7:$W7) -> 3.718406
A8: 2018 | B8: 7 | C8: 5.3108947 | D8: 4.157 | E8: 6.547377 | F8: 7.3585 | G8: 3.840359 | H8: 7.5560877 | I8: 8.1259167 | J8: 16.64225 | K8: 6.45975 | L8: 5.7223507 | M8: 12.976133 | N8: 11.742642 | O8: 7.8728485 | P8: 6.5397719 | Q8: 6.7561875 | R8: 8.2746667 | S8: 16.210396 | T8: 18.564667 | U8: 20.908808 | V8: 14.218779 | W8: 16.065541 | Y8: 7 | Z8: =AVERAGE(C8:G8) -> 5.4428261 | AA8: =AVERAGE(H8:L8) -> 8.901271 | AB8: =AVERAGE(M8:R8) -> 9.0270414 | AC8: =AVERAGE(S8:W8) -> 17.193638 | AD8: =STDEV($C8:$G8) -> 1.5106699 | AE8: =STDEV($H8:$L8) -> 4.4271889 | AF8: =STDEV($M8:$R8) -> 2.6911455 | AG8: =STDEV($S8:$W8) -> 2.5870523
A9: 2018 | B9: 8 | C9: 5.5383263 | D9: 9.1200286 | E9: 9.9427341 | F9: 8.9825714 | G9: 6.1355385 | H9: 7.9263772 | I9: 9.1208194 | J9: 20.001833 | K9: 6.718625 | L9: 5.6657164 | M9: 14.208074 | N9: 15.415396 | O9: 13.997091 | P9: 7.8121053 | Q9: 8.002 | R9: 8.9335208 | S9: 17.698257 | T9: 16.777667 | U9: 23.438508 | V9: 17.405397 | W9: 16.815184 | Y9: 8 | Z9: =AVERAGE(C9:G9) -> 7.9438398 | AA9: =AVERAGE(H9:L9) -> 9.8866743 | AB9: =AVERAGE(M9:R9) -> 11.394698 | AC9: =AVERAGE(S9:W9) -> 18.427003 | AD9: =STDEV($C9:$G9) -> 1.9694168 | AE9: =STDEV($H9:$L9) -> 5.8008353 | AF9: =STDEV($M9:$R9) -> 3.5001803 | AG9: =STDEV($S9:$W9) -> 2.8287899
A10: 2018 | B10: 9 | C10: 7.066 | D10: 9.9472 | E10: 10.563302 | F10: 9.8193036 | G10: 6.7364872 | H10: 10.509465 | I10: 10.161667 | J10: 24.639292 | K10: 7.002125 | L10: 7.6033881 | M10: 14.023698 | N10: 18.209057 | O10: 16.715 | P10: 10.062667 | Q10: 8.002 | R10: 9.9223333 | S10: 20.081333 | T10: 25.259974 | U10: 25.31674 | V10: 13.653529 | W10: 21.52685 | Y10: 9 | Z10: =AVERAGE(C10:G10) -> 8.8264585 | AA10: =AVERAGE(H10:L10) -> 11.983187 | AB10: =AVERAGE(M10:R10) -> 12.822459 | AC10: =AVERAGE(S10:W10) -> 21.167685 | AD10: =STDEV($C10:$G10) -> 1.7836494 | AE10: =STDEV($H10:$L10) -> 7.2398273 | AF10: =STDEV($M10:$R10) -> 4.1200556 | AG10: =STDEV($S10:$W10) -> 4.7888721
A11: 2018 | B11: 10 | C11: 8.2941053 | D11: 9.9472 | E11: 12.061575 | F11: 17.178 | G11: 9.5750769 | H11: 12.34039 | I11: 12.201417 | J11: 28.5655 | K11: 6.994875 | L11: 8.0407836 | M11: 14.898886 | N11: 19.605887 | O11: 19.376515 | P11: 10.079509 | Q11: 12.202469 | R11: 12.695458 | S11: 24.342028 | T11: 29.882026 | U11: 28.777661 | V11: 16.341985 | W11: 23.074213 | Y11: 10 | Z11: =AVERAGE(C11:G11) -> 11.411192 | AA11: =AVERAGE(H11:L11) -> 13.628593 | AB11: =AVERAGE(M11:R11) -> 14.809787 | AC11: =AVERAGE(S11:W11) -> 24.483582 | AD11: =STDEV($C11:$G11) -> 3.4967804 | AE11: =STDEV($H11:$L11) -> 8.6896104 | AF11: =STDEV($M11:$R11) -> 3.9372464 | AG11: =STDEV($S11:$W11) -> 5.3822455
A12: 2018 | B12: 11 | C12: 9.2668526 | D12: 12.958114 | E12: 10.748643 | F12: 18.1495 | G12: 13.494564 | H12: 15.252079 | I12: 13.799917 | J12: 24.949667 | K12: 8.929625 | L12: 10.893739 | M12: 14.580219 | N12: 22.858415 | O12: 21.860652 | P12: 11.983316 | Q12: 14.72275 | R12: 14.219083 | S12: 26.079521 | T12: 26.800949 | U12: 25.576141 | V12: 17.777044 | W12: 22.333039 | Y12: 11 | Z12: =AVERAGE(C12:G12) -> 12.923535 | AA12: =AVERAGE(H12:L12) -> 14.765005 | AB12: =AVERAGE(M12:R12) -> 16.704072 | AC12: =AVERAGE(S12:W12) -> 23.713339 | AD12: =STDEV($C12:$G12) -> 3.3815478 | AE12: =STDEV($H12:$L12) -> 6.2035138 | AF12: =STDEV($M12:$R12) -> 4.5025181 | AG12: =STDEV($S12:$W12) -> 3.733196
A13: 2018 | B13: 12 | C13: 9.9283158 | D13: 20.4854 | E13: 13.211004 | F13: 20.57825 | G13: 16.142205 | H13: 18.840886 | I13: 15.438264 | J13: 29.762375 | K13: 8.940375 | L13: 11.894269 | M13: 14.691229 | N13: 21.874063 | O13: 22.450848 | P13: 14.531456 | Q13: 14.72275 | R13: 12.115333 | S13: 26.865236 | T13: 27.033872 | U13: 30.052124 | V13: 18.4055 | W13: 25.214971 | Y13: 12 | Z13: =AVERAGE(C13:G13) -> 16.069035 | AA13: =AVERAGE(H13:L13) -> 16.975234 | AB13: =AVERAGE(M13:R13) -> 16.730947 | AC13: =AVERAGE(S13:W13) -> 25.514341 | AD13: =STDEV($C13:$G13) -> 4.6292393 | AE13: =STDEV($H13:$L13) -> 8.0580562 | AF13: =STDEV($M13:$R13) -> 4.3244391 | AG13: =STDEV($S13:$W13) -> 4.3402365
A14: 2018 | B14: 13 | C14: 9.6324 | D14: 20.4854 | E14: 14.368278 | F14: 22.55625 | G14: 17.54341 | H14: 21.38289 | I14: 19.549 | J14: 31.869833 | K14: 10.588 | L14: 11.996873 | M14: 16.127337 | N14: 19.905358 | O14: 21.5705 | P14: 16.866333 | Q14: 16.34475 | R14: 17.268833 | S14: 23.905833 | T14: 32.520051 | U14: 32.275384 | V14: 17.921309 | W14: 27.04901 | Y14: 13 | Z14: =AVERAGE(C14:G14) -> 16.917148 | AA14: =AVERAGE(H14:L14) -> 19.077319 | AB14: =AVERAGE(M14:R14) -> 18.013852 | AC14: =AVERAGE(S14:W14) -> 26.734317 | AD14: =STDEV($C14:$G14) -> 5.1109782 | AE14: =STDEV($H14:$L14) -> 8.5350427 | AF14: =STDEV($M14:$R14) -> 2.2110736 | AG14: =STDEV($S14:$W14) -> 6.1226345
A15: 2018 | B15: 14 | C15: 14.382716 | D15: 20.4854 | E15: 14.778817 | F15: 24.53425 | G15: 18.633923 | H15: 28.745465 | I15: 21.041278 | J15: 34.119375 | K15: 11.20175 | L15: 10.309769 | M15: 18.901493 | N15: 21.72805 | O15: 20.75403 | P15: 19.222825 | Q15: 17.96675 | R15: 22.422333 | S15: 25.06625 | T15: 32.805128 | U15: 29.512492 | V15: 22.662691 | W15: 26.69442 | Y15: 14 | Z15: =AVERAGE(C15:G15) -> 18.563021 | AA15: =AVERAGE(H15:L15) -> 21.083527 | AB15: =AVERAGE(M15:R15) -> 20.165914 | AC15: =AVERAGE(S15:W15) -> 27.348196 | AD15: =STDEV($C15:$G15) -> 4.2175613 | AE15: =STDEV($H15:$L15) -> 10.516223 | AF15: =STDEV($M15:$R15) -> 1.7436788 | AG15: =STDEV($S15:$W15) -> 3.9386209
A16: 2018 | B16: 15 | C16: 16.946453 | D16: 20.301543 | E16: 14.266651 | F16: 24.972643 | G16: 21.756731 | H16: 28.694162 | I16: 20.845222 | J16: 33.5125 | K16: 10.989125 | L16: 12.725985 | M16: 21.389994 | N16: 22.639396 | O16: 21.461394 | P16: 19.907474 | Q16: 17.96675 | R16: 24.510146 | S16: 31.282708 | T16: 33.724615 | U16: 30.417785 | V16: 25.251324 | W16: 27.484261 | Y16: 15 | Z16: =AVERAGE(C16:G16) -> 19.648804 | AA16: =AVERAGE(H16:L16) -> 21.353399 | AB16: =AVERAGE(M16:R16) -> 21.312526 | AC16: =AVERAGE(S16:W16) -> 29.632139 | AD16: =STDEV($C16:$G16) -> 4.167822 | AE16: =STDEV($H16:$L16) -> 9.7959077 | AF16: =STDEV($M16:$R16) -> 2.2441885 | AG16: =STDEV($S16:$W16) -> 3.3126616
A17: 2018 | B17: 16 | C17: 18.573758 | D17: 20.228 | E17: 15.799683 | F17: 25.148 | G17: 18.366654 | H17: 29.802789 | I17: 23.703167 | J17: 37.707 | K17: 10.974125 | L17: 18.373 | M17: 22.46911 | N17: 21.304 | O17: 23.808545 | P17: 20.44586 | Q17: 17.886125 | R17: 27.021333 | S17: 30.263403 | T17: 35.146513 | U17: 35.810576 | V17: 22.717809 | W17: 32.796126 | Y17: 16 | Z17: =AVERAGE(C17:G17) -> 19.623219 | AA17: =AVERAGE(H17:L17) -> 24.112016 | AB17: =AVERAGE(M17:R17) -> 22.155829 | AC17: =AVERAGE(S17:W17) -> 31.346885 | AD17: =STDEV($C17:$G17) -> 3.4709048 | AE17: =STDEV($H17:$L17) -> 10.282462 | AF17: =STDEV($M17:$R17) -> 3.1107147 | AG17: =STDEV($S17:$W17) -> 5.2937912
... A26: 2018 | B26: 25 | C26: 18.3642 | D26: 19.9026 | E26: 15.185921 | F26: 28.9055 | G26: 25.311 | H26: 32.873684 | I26: 24.266 | J26: 25.3205 | K26: 33.695 | L26: 25.859858 | M26: 20.554435 | N26: 13.028679 | O26: 27.266 | P26: 21.887 | Q26: 17.900667 | R26: 35.932667 | S26: 22.560736 | T26: 29.684705 | U26: 29.58 | V26: 30.581956 | W26: 33.374447 | Y26: 25 | Z26: =AVERAGE(C26:G26) -> 21.533844 | AA26: =AVERAGE(H26:L26) -> 28.403008 | AB26: =AVERAGE(M26:R26) -> 22.761575 | AC26: =AVERAGE(S26:W26) -> 29.156369 | AD26: =STDEV($C26:$G26) -> 5.5138904 | AE26: =STDEV($H26:$L26) -> 4.5021225 | AF26: =STDEV($M26:$R26) -> 7.9719701 | AG26: =STDEV($S26:$W26) -> 3.9932898
B28: Helper Column | D28: Repeat Times | E28: Helper Column | F28: Product | H28: Final | J28: 1
B29: 1 | C29: 3.5716667 | D29: 25 | E29: 1 | F29: =VLOOKUP(E29,$B$29:$C$97,2) -> 3.5716667 | G29: =INT((ROW(G1)-1)/69)+1 -> 1 | H29: =AVERAGEIF($G$29:$G$2538, J28, $F$29:$F$2538) -> 3.9176232 | J29: 2
B30: =B29+D29 -> 26 | C30: 3.0186667 | D30: 25 | E30: 2 | F30: =VLOOKUP(E30,$B$29:$C$97,2) -> 3.5716667 | G30: =INT((ROW(G2)-1)/69)+1 -> 1 | H30: =AVERAGEIF($G$29:$G$2538, J29, $F$29:$F$2538) -> 7.3835797 | J30: 3
B31: =B30+D30 -> 51 | C31: 5.5556667 | D31: 25 | E31: 3 | F31: =VLOOKUP(E31,$B$29:$C$97,2) -> 3.5716667 | G31: =INT((ROW(G3)-1)/69)+1 -> 1 | H31: =AVERAGEIF($G$29:$G$2538, J30, $F$29:$F$2538) -> 9.9284203 | J31: 4
B32: =B31+D31 -> 76 | C32: 7.7986667 | D32: 25 | E32: 4 | F32: =VLOOKUP(E32,$B$29:$C$97,2) -> 3.5716667 | G32: =INT((ROW(G4)-1)/69)+1 -> 1 | H32: =AVERAGEIF($G$29:$G$2538, J31, $F$29:$F$2538) -> 12.983217 | J32: 5
B33: =B32+D32 -> 101 | C33: 6.7923333 | D33: 25 | E33: 5 | F33: =VLOOKUP(E33,$B$29:$C$97,2) -> 3.5716667 | G33: =INT((ROW(G5)-1)/69)+1 -> 1 | H33: =AVERAGEIF($G$29:$G$2538, J32, $F$29:$F$2538) -> 12.795952 | J33: 6
B34: =B33+D33 -> 126 | C34: 8.566 | D34: 25 | E34: 6 | F34: =VLOOKUP(E34,$B$29:$C$97,2) -> 3.5716667 | G34: =INT((ROW(G6)-1)/69)+1 -> 1 | H34: =AVERAGEIF($G$29:$G$2538, J33, $F$29:$F$2538) -> 13.7893 | J34: 7
B35: =B34+D34 -> 151 | C35: 8.805 | D35: 25 | E35: 7 | F35: =VLOOKUP(E35,$B$29:$C$97,2) -> 3.5716667 | G35: =INT((ROW(G7)-1)/69)+1 -> 1 | H35: =AVERAGEIF($G$29:$G$2538, J34, $F$29:$F$2538) -> 16.065541 | J35: 8
B36: =B35+D35 -> 176 | C36: 11.104667 | D36: 25 | E36: 8 | F36: =VLOOKUP(E36,$B$29:$C$97,2) -> 3.5716667 | G36: =INT((ROW(G8)-1)/69)+1 -> 1 | H36: =AVERAGEIF($G$29:$G$2538, J35, $F$29:$F$2538) -> 16.815184 | J36: 9
B37: =B36+D36 -> 201 | C37: 12.075333 | D37: 25 | E37: 9 | F37: =VLOOKUP(E37,$B$29:$C$97,2) -> 3.5716667 | G37: =INT((ROW(G9)-1)/69)+1 -> 1 | H37: =AVERAGEIF($G$29:$G$2538, J36, $F$29:$F$2538) -> 21.52685 | J37: 10
B38: =B37+D37 -> 226 | C38: 13.356 | D38: 25 | E38: 10 | F38: =VLOOKUP(E38,$B$29:$C$97,2) -> 3.5716667 | G38: =INT((ROW(G10)-1)/69)+1 -> 1 | H38: =AVERAGEIF($G$29:$G$2538, J37, $F$29:$F$2538) -> 23.074213 | J38: 11
B39: =B38+D38 -> 251 | C39: 13.340333 | D39: 25 | E39: 11 | F39: =VLOOKUP(E39,$B$29:$C$97,2) -> 3.5716667 | G39: =INT((ROW(G11)-1)/69)+1 -> 1 | H39: =AVERAGEIF($G$29:$G$2538, J38, $F$29:$F$2538) -> 22.333039 | J39: 12
B40: =B39+D39 -> 276 | C40: 11.077667 | D40: 25 | E40: 12 | F40: =VLOOKUP(E40,$B$29:$C$97,2) -> 3.5716667 | G40: =INT((ROW(G12)-1)/69)+1 -> 1 | H40: =AVERAGEIF($G$29:$G$2538, J39, $F$29:$F$2538) -> 25.214971 | J40: 13
B41: =B40+D40 -> 301 | C41: 11.320667 | D41: 25 | E41: 13 | F41: =VLOOKUP(E41,$B$29:$C$97,2) -> 3.5716667 | G41: =INT((ROW(G13)-1)/69)+1 -> 1 | H41: =AVERAGEIF($G$29:$G$2538, J40, $F$29:$F$2538) -> 27.04901 | J41: 14
... B52: =B51+D51 -> 576 | C52: 22.394667 | D52: 25 | E52: 24 | F52: =VLOOKUP(E52,$B$29:$C$97,2) -> 3.5716667 | G52: =INT((ROW(G24)-1)/69)+1 -> 1 | H52: =AVERAGEIF($G$29:$G$2538, J51, $F$29:$F$2538) -> 32.879449 | J52: 25
B53: =B52+D52 -> 601 | C53: 21.437667 | D53: 25 | E53: 25 | F53: =VLOOKUP(E53,$B$29:$C$97,2) -> 3.5716667 | G53: =INT((ROW(G25)-1)/69)+1 -> 1 | H53: =AVERAGEIF($G$29:$G$2538, J52, $F$29:$F$2538) -> 33.374447
B54: =B53+D53 -> 626 | C54: 22.406667 | D54: 25 | E54: 26 | F54: =VLOOKUP(E54,$B$29:$C$97,2) -> 3.0186667 | G54: =INT((ROW(G26)-1)/69)+1 -> 1
B55: =B54+D54 -> 651 | C55: 24.168333 | D55: 25 | E55: 27 | F55: =VLOOKUP(E55,$B$29:$C$97,2) -> 3.0186667 | G55: =INT((ROW(G27)-1)/69)+1 -> 1
B56: =B55+D55 -> 676 | C56: 22.799667 | D56: 25 | E56: 28 | F56: =VLOOKUP(E56,$B$29:$C$97,2) -> 3.0186667 | G56: =INT((ROW(G28)-1)/69)+1 -> 1
B57: =B56+D56 -> 701 | C57: 21.948333 | D57: 25 | E57: 29 | F57: =VLOOKUP(E57,$B$29:$C$97,2) -> 3.0186667 | G57: =INT((ROW(G29)-1)/69)+1 -> 1
B58: =B57+D57 -> 726 | C58: 21.140667 | D58: 25 | E58: 30 | F58: =VLOOKUP(E58,$B$29:$C$97,2) -> 3.0186667 | G58: =INT((ROW(G30)-1)/69)+1 -> 1
B59: =B58+D58 -> 751 | C59: 26.195333 | D59: 25 | E59: 31 | F59: =VLOOKUP(E59,$B$29:$C$97,2) -> 3.0186667 | G59: =INT((ROW(G31)-1)/69)+1 -> 1
...

Sheet Standardized - 2019
A1: Year | B1: Standardized Cell Number | C1: Under42 | D1: WAS27 | E1: WAS03 | F1: WAS21 | G1: WAS36 | H1: WAS49 | I1: GT-1 | J1: GT-3 | K1: GT-4 | L1: WAS61 | M1: AboveP1 | N1: WAS51 | O1: WAS50 | P1: WAS42 | Q1: WAS01 | R1: WAS04 | S1: WAS63 | T1: WAS64 | U1: WAS48 | V1: WAS57 | W1: WAS65 | Y1: Standardized Ring | Z1: DF-Cliff | AA1: DF-Soil | AB1: ES-Cliff | AC1: ES-Soil | AE1: Species | AF1: Site | AG1: Average LD | AH1: SD | AI1: SE
A2: 2019 | B2: 1 | C2: 3.4764 | D2: 2.387 | E2: 2.2710495 | F2: 1.066 | G2: 3.8354661 | H2: 1.7873772 | I2: 2.0880606 | J2: 6.4221574 | K2: 4.9678015 | L2: 4.497131 | M2: 3.9779329 | N2: 3.1628679 | O2: 1.536963 | P2: 2.6415 | Q2: 0.755 | R2: 6.085 | S2: 3.5051452 | T2: 4.5017895 | U2: 1.9490303 | V2: 1.5093333 | W2: 5.2401596 | Y2: 1 | Z2: =AVERAGE(C2:G2) -> 2.6071831 | AA2: =AVERAGE(H2:L2) -> 3.9525055 | AB2: =AVERAGE(M2:R2) -> 3.026544 | AC2: =AVERAGE(S2:W2) -> 3.3410916 | AE2: Spruce | AF2: Soil | AG2: =AVERAGE(S2:W26) -> 23.834772 | AH2: =STDEV(S2:W26) -> 10.160924 | AI2: =AH2/SQRT(125) -> 0.90882069
A3: 2019 | B3: 2 | C3: 4.4119895 | D3: 2.387 | E3: 3.6970856 | F3: 1.066 | G3: 3.7479831 | H3: 3.429386 | I3: 3.392596 | J3: 8.8441481 | K3: 7.4829033 | L3: 6.6336905 | M3: 5.3485702 | N3: 4.9385283 | O3: 2.0542284 | P3: 4.8770463 | Q3: 0.755 | R3: 5.5956667 | S3: 4.9939624 | T3: 7.7824211 | U3: 5.5776667 | V3: 2.0123333 | W3: 12.657025 | Y3: 2 | Z3: =AVERAGE(C3:G3) -> 3.0620116 | AA3: =AVERAGE(H3:L3) -> 5.9565448 | AB3: =AVERAGE(M3:R3) -> 3.9281733 | AC3: =AVERAGE(S3:W3) -> 6.6046816 | AE3: Spruce | AF3: Cliff | AG3: =AVERAGE($M$2:$Q$26) -> 15.618312 | AH3: =STDEV($M$2:$Q$26) -> 7.3800017 | AI3: =AH3/SQRT(125) -> 0.66008742
A4: 2019 | B4: 3 | C4: 5.9218737 | D4: 2.387 | E4: 3.6831036 | F4: 1.8591458 | G4: 3.6982599 | H4: 3.6599547 | I4: 5.2716061 | J4: 9.6353241 | K4: 9.4302799 | L4: 6.3694286 | M4: 6.6349476 | N4: 6.3984151 | O4: 3.3073333 | P4: 7.3316296 | Q4: 0.755 | R4: 4.617 | S4: 8.0870968 | T4: 8.6397193 | U4: 7.4216061 | V4: 6.324 | W4: 9.8692163 | Y4: 3 | Z4: =AVERAGE(C4:G4) -> 3.5098766 | AA4: =AVERAGE(H4:L4) -> 6.8733187 | AB4: =AVERAGE(M4:R4) -> 4.8407209 | AC4: =AVERAGE(S4:W4) -> 8.0683277 | AE4: Douglas Fir | AF4: Soil | AG4: =AVERAGE($H$2:$L$26) -> 20.520984 | AH4: =STDEV($H$2:$L$26) -> 10.093184 | AI4: =AH4/SQRT(125) -> 0.90276186
A5: 2019 | B5: 4 | C5: 7.6932316 | D5: 2.5652857 | E5: 6.560036 | F5: 1.93125 | G5: 4.0746723 | H5: 5.9794386 | I5: 6.6410404 | J5: 11.828046 | K5: 9.3378448 | L5: 5.6673452 | M5: 7.840914 | N5: 7.7370943 | O5: 4.9017654 | P5: 10.9435 | Q5: 2.075375 | R5: 5.2425556 | S5: 9.1457312 | T5: 10.265386 | U5: 13.533333 | V5: 8.139 | W5: 13.615748 | Y5: 4 | Z5: =AVERAGE(C5:G5) -> 4.5648951 | AA5: =AVERAGE(H5:L5) -> 7.8907431 | AB5: =AVERAGE(M5:R5) -> 6.4568674 | AC5: =AVERAGE(S5:W5) -> 10.93984 | AE5: Douglas Fir | AF5: Cliff | AG5: =AVERAGE($C$2:$G$26) -> 14.762523 | AH5: =STDEV($C$2:$G$26) -> 8.4134822 | AI5: =AH5/SQRT(125) -> 0.75252473
A6: 2019 | B6: 5 | C6: 6.3114 | D6: 2.803 | E6: 5.8169009 | F6: 4.429375 | G6: 4.7729266 | H6: 7.8327325 | I6: 7.1024545 | J6: 10.881991 | K6: 9.6930153 | L6: 5.9484167 | M6: 7.7324151 | N6: 9.1491321 | O6: 7.040358 | P6: 11.054194 | Q6: 2.264 | R6: 5.5553333 | S6: 9.897043 | T6: 9.7142807 | U6: 13.15897 | V6: 12.945667 | W6: 15.161167 | Y6: 5 | Z6: =AVERAGE(C6:G6) -> 4.8267205 | AA6: =AVERAGE(H6:L6) -> 8.2917219 | AB6: =AVERAGE(M6:R6) -> 7.1325722 | AC6: =AVERAGE(S6:W6) -> 12.175425
A7: 2019 | B7: 6 | C7: 7.9305368 | D7: 2.803 | E7: 4.5249685 | F7: 4.929 | G7: 5.5552881 | H7: 10.020789 | I7: 8.5826768 | J7: 12.441407 | K7: 10.499824 | L7: 6.8061012 | M7: 8.6081006 | N7: 9.4647547 | O7: 8.3105556 | P7: 12.529519 | Q7: 2.264 | R7: 4.8563333 | S7: 9.1967151 | T7: 10.904456 | U7: 13.052061 | V7: 16.401333 | W7: 18.857954 | Y7: 6 | Z7: =AVERAGE(C7:G7) -> 5.1485587 | AA7: =AVERAGE(H7:L7) -> 9.6701599 | AB7: =AVERAGE(M7:R7) -> 7.6722105 | AC7: =AVERAGE(S7:W7) -> 13.682504
A8: 2019 | B8: 7 | C8: 10.174821 | D8: 2.803 | E8: 7.1462613 | F8: 7.749375 | G8: 6.6996893 | H8: 9.2364649 | I8: 10.848566 | J8: 19.757306 | K8: 10.342076 | L8: 9.7596488 | M8: 8.5600168 | N8: 8.5944151 | O8: 9.1159136 | P8: 14.415519 | Q8: 9.0565 | R8: 5.2935556 | S8: 14.25078 | T8: 13.271684 | U8: 17.619121 | V8: 13.114333 | W8: 21.004965 | Y8: 7 | Z8: =AVERAGE(C8:G8) -> 6.9146293 | AA8: =AVERAGE(H8:L8) -> 11.988812 | AB8: =AVERAGE(M8:R8) -> 9.1726533 | AC8: =AVERAGE(S8:W8) -> 15.852177
A9: 2019 | B9: 8 | C9: 12.724758 | D9: 9.4659143 | E9: 7.9361892 | F9: 8.6895 | G9: 8.3280847 | H9: 10.496904 | I9: 13.542152 | J9: 28.163046 | K9: 10.37142 | L9: 12.075405 | M9: 9.4284654 | N9: 10.731245 | O9: 10.055309 | P9: 15.597333 | Q9: 11.320667 | R9: 6.168 | S9: 16.342151 | T9: 18.275842 | U9: 20.875667 | V9: 14.848667 | W9: 24.988691 | Y9: 8 | Z9: =AVERAGE(C9:G9) -> 9.4288892 | AA9: =AVERAGE(H9:L9) -> 14.929785 | AB9: =AVERAGE(M9:R9) -> 10.55017 | AC9: =AVERAGE(S9:W9) -> 19.066203
A10: 2019 | B10: 9 | C10: 14.9276 | D10: 10.5764 | E10: 9.3769685 | F10: 13.336833 | G10: 7.5731864 | H10: 15.781355 | I10: 16.118444 | J10: 30.067889 | K10: 11.956705 | L10: 12.295417 | M10: 11.153962 | N10: 12.838113 | O10: 12.484222 | P10: 17.99 | Q10: 11.320667 | R10: 9.0053333 | S10: 18.017629 | T10: 22.239667 | U10: 26.549121 | V10: 23.896333 | W10: 25.719794 | Y10: 9 | Z10: =AVERAGE(C10:G10) -> 11.158198 | AA10: =AVERAGE(H10:L10) -> 17.243962 | AB10: =AVERAGE(M10:R10) -> 12.465383 | AC10: =AVERAGE(S10:W10) -> 23.284509
A11: 2019 | B11: 10 | C11: 13.785547 | D11: 10.5764 | E11: 11.101378 | F11: 15.6605 | G11: 9.052339 | H11: 17.992557 | I11: 19.348263 | J11: 32.492065 | K11: 11.289313 | L11: 14.52069 | M11: 14.735723 | N11: 11.877887 | O11: 16.025049 | P11: 19.806796 | Q11: 16.694625 | R11: 10.424 | S11: 21.287 | T11: 24.498526 | U11: 27.753121 | V11: 18.685 | W11: 28.288117 | Y11: 10 | Z11: =AVERAGE(C11:G11) -> 12.035233 | AA11: =AVERAGE(H11:L11) -> 19.128578 | AB11: =AVERAGE(M11:R11) -> 14.927347 | AC11: =AVERAGE(S11:W11) -> 24.102353
A12: 2019 | B12: 11 | C12: 14.8364 | D12: 13.096971 | E12: 11.690459 | F12: 19.080146 | G12: 10.523345 | H12: 22.048368 | I12: 19.695879 | J12: 29.746861 | K12: 14.275738 | L12: 14.64978 | M12: 17.301094 | N12: 13.373585 | O12: 19.823185 | P12: 21.42 | Q12: 19.919 | R12: 14.878667 | S12: 19.27357 | T12: 28.588105 | U12: 29.757152 | V12: 20.417333 | W12: 31.770152 | Y12: 11 | Z12: =AVERAGE(C12:G12) -> 13.845464 | AA12: =AVERAGE(H12:L12) -> 20.083325 | AB12: =AVERAGE(M12:R12) -> 17.785922 | AC12: =AVERAGE(S12:W12) -> 25.961262
A13: 2019 | B13: 12 | C13: 16.610884 | D13: 19.3984 | E13: 13.119509 | F13: 21.52275 | G13: 13.482147 | H13: 26.262404 | I13: 20.203455 | J13: 31.224444 | K13: 16.688107 | L13: 17.957006 | M13: 16.025765 | N13: 13.367585 | O13: 17.483296 | P13: 19.151556 | Q13: 19.919 | R13: 16.202444 | S13: 23.783763 | T13: 30.775684 | U13: 30.899515 | V13: 17.543333 | W13: 33.167642 | Y13: 12 | Z13: =AVERAGE(C13:G13) -> 16.826738 | AA13: =AVERAGE(H13:L13) -> 22.467083 | AB13: =AVERAGE(M13:R13) -> 17.024941 | AC13: =AVERAGE(S13:W13) -> 27.233988
A14: 2019 | B14: 13 | C14: 18.0428 | D14: 19.3984 | E14: 11.741685 | F14: 23.798375 | G14: 19.701424 | H14: 28.07843 | I14: 19.881657 | J14: 34.236167 | K14: 20.106405 | L14: 21.176381 | M14: 15.901509 | N14: 13.891019 | O14: 21.40484 | P14: 19.245333 | Q14: 19.469333 | R14: 18.85 | S14: 31.220828 | T14: 29.625263 | U14: 33.820773 | V14: 19.942 | W14: 34.37505 | Y14: 13 | Z14: =AVERAGE(C14:G14) -> 18.536537 | AA14: =AVERAGE(H14:L14) -> 24.695808 | AB14: =AVERAGE(M14:R14) -> 18.127006 | AC14: =AVERAGE(S14:W14) -> 29.796783
A15: 2019 | B15: 14 | C15: 18.048863 | D15: 19.3984 | E15: 15.199829 | F15: 26.074 | G15: 20.345051 | H15: 28.618377 | I15: 19.659758 | J15: 30.920806 | K15: 21.271738 | L15: 19.66719 | M15: 13.479258 | N15: 15.506528 | O15: 19.389333 | P15: 20.155926 | Q15: 19.019667 | R15: 22.567556 | S15: 27.418005 | T15: 28.328684 | U15: 35.569636 | V15: 23.416333 | W15: 32.12311 | Y15: 14 | Z15: =AVERAGE(C15:G15) -> 19.813229 | AA15: =AVERAGE(H15:L15) -> 24.027574 | AB15: =AVERAGE(M15:R15) -> 18.353045 | AC15: =AVERAGE(S15:W15) -> 29.371154
A16: 2019 | B16: 15 | C16: 19.886842 | D16: 22.0004 | E16: 14.040027 | F16: 26.535667 | G16: 20.338712 | H16: 26.38536 | I16: 20.440768 | J16: 30.233806 | K16: 25.356944 | L16: 18.987143 | M16: 10.822415 | N16: 18.776755 | O16: 23.17663 | P16: 24.422 | Q16: 19.019667 | R16: 24.426333 | S16: 24.676844 | T16: 27.976825 | U16: 29.936485 | V16: 21.733333 | W16: 28.425624 | Y16: 15 | Z16: =AVERAGE(C16:G16) -> 20.56033 | AA16: =AVERAGE(H16:L16) -> 24.280804 | AB16: =AVERAGE(M16:R16) -> 20.1073 | AC16: =AVERAGE(S16:W16) -> 26.549822
A17: 2019 | B17: 16 | C17: 21.868253 | D17: 23.0412 | E17: 12.279347 | F17: 27.182 | G17: 18.558006 | H17: 26.995838 | I17: 23.100808 | J17: 33.675148 | K17: 25.889936 | L17: 26.819143 | M17: 13.407501 | N17: 18.428226 | O17: 22.519951 | P17: 23.505019 | Q17: 20.216292 | R17: 26.416 | S17: 26.956538 | T17: 29.538088 | U17: 35.805758 | V17: 23.010333 | W17: 34.020837 | Y17: 16 | Z17: =AVERAGE(C17:G17) -> 20.585761 | AA17: =AVERAGE(H17:L17) -> 27.296175 | AB17: =AVERAGE(M17:R17) -> 20.748831 | AC17: =AVERAGE(S17:W17) -> 29.866311
... A26: 2019 | B26: 25 | C26: 18.058 | D26: 24.2126 | E26: 18.000214 | F26: 29.437667 | G26: 20.420345 | H26: 32.278789 | I26: 19.220056 | J26: 37.218889 | K26: 30.294936 | L26: 26.792804 | M26: 19.726953 | N26: 23.18 | O26: 28.429346 | P26: 28.7415 | Q26: 19.079 | R26: 28.747667 | S26: 28.419476 | T26: 35.069404 | U26: 40.535303 | V26: 27.887333 | W26: 34.516582 | Y26: 25 | Z26: =AVERAGE(C26:G26) -> 22.025765 | AA26: =AVERAGE(H26:L26) -> 29.161095 | AB26: =AVERAGE(M26:R26) -> 24.650744 | AC26: =AVERAGE(S26:W26) -> 33.285619
B28: Helper Column | D28: Repeat Times | E28: Helper Column | F28: Product | H28: Final | J28: 1
B29: 1 | C29: 0.755 | D29: 25 | E29: 1 | F29: =VLOOKUP(E29,$B$29:$C$124,2) -> 0.755 | G29: =INT(((ROW(G1)-1)/75)+1) -> 1 | H29: =AVERAGEIF($G$29:$G$3417, J28, $F$29:$F$3387) -> 1.5093333 | J29: 2
B30: =B29+D29 -> 26 | C30: 2.264 | D30: 25 | E30: 2 | F30: =VLOOKUP(E30,$B$29:$C$124,2) -> 0.755 | G30: =INT(((ROW(G2)-1)/75)+1) -> 1 | H30: =AVERAGEIF($G$29:$G$3417, J29, $F$29:$F$3387) -> 2.0123333 | J30: 3
B31: =B30+D30 -> 51 | C31: 1.509 | D31: 25 | E31: 3 | F31: =VLOOKUP(E31,$B$29:$C$124,2) -> 0.755 | G31: =INT(((ROW(G3)-1)/75)+1) -> 1 | H31: =AVERAGEIF($G$29:$G$3417, J30, $F$29:$F$3387) -> 6.324 | J31: 4
B32: =B31+D31 -> 76 | C32: 1.509 | D32: 25 | E32: 4 | F32: =VLOOKUP(E32,$B$29:$C$124,2) -> 0.755 | G32: =INT(((ROW(G4)-1)/75)+1) -> 1 | H32: =AVERAGEIF($G$29:$G$3417, J31, $F$29:$F$3387) -> 8.139 | J32: 5
B33: =B32+D32 -> 101 | C33: 1.509 | D33: 25 | E33: 5 | F33: =VLOOKUP(E33,$B$29:$C$124,2) -> 0.755 | G33: =INT(((ROW(G5)-1)/75)+1) -> 1 | H33: =AVERAGEIF($G$29:$G$3417, J32, $F$29:$F$3387) -> 12.945667 | J33: 6
B34: =B33+D33 -> 126 | C34: 3.019 | D34: 25 | E34: 6 | F34: =VLOOKUP(E34,$B$29:$C$124,2) -> 0.755 | G34: =INT(((ROW(G6)-1)/75)+1) -> 1 | H34: =AVERAGEIF($G$29:$G$3417, J33, $F$29:$F$3387) -> 16.401333 | J34: 7
B35: =B34+D34 -> 151 | C35: 6.834 | D35: 25 | E35: 7 | F35: =VLOOKUP(E35,$B$29:$C$124,2) -> 0.755 | G35: =INT(((ROW(G7)-1)/75)+1) -> 1 | H35: =AVERAGEIF($G$29:$G$3417, J34, $F$29:$F$3387) -> 13.114333 | J35: 8
B36: =B35+D35 -> 176 | C36: 4.591 | D36: 25 | E36: 8 | F36: =VLOOKUP(E36,$B$29:$C$124,2) -> 0.755 | G36: =INT(((ROW(G8)-1)/75)+1) -> 1 | H36: =AVERAGEIF($G$29:$G$3417, J35, $F$29:$F$3387) -> 14.848667 | J36: 9
B37: =B36+D36 -> 201 | C37: 7.547 | D37: 25 | E37: 9 | F37: =VLOOKUP(E37,$B$29:$C$124,2) -> 0.755 | G37: =INT(((ROW(G9)-1)/75)+1) -> 1 | H37: =AVERAGEIF($G$29:$G$3417, J36, $F$29:$F$3387) -> 23.896333 | J37: 10
B38: =B37+D37 -> 226 | C38: 6.958 | D38: 25 | E38: 10 | F38: =VLOOKUP(E38,$B$29:$C$124,2) -> 0.755 | G38: =INT(((ROW(G10)-1)/75)+1) -> 1 | H38: =AVERAGEIF($G$29:$G$3417, J37, $F$29:$F$3387) -> 18.685 | J38: 11
B39: =B38+D38 -> 251 | C39: 11.421 | D39: 25 | E39: 11 | F39: =VLOOKUP(E39,$B$29:$C$124,2) -> 0.755 | G39: =INT(((ROW(G11)-1)/75)+1) -> 1 | H39: =AVERAGEIF($G$29:$G$3417, J38, $F$29:$F$3387) -> 20.417333 | J39: 12
B40: =B39+D39 -> 276 | C40: 6.038 | D40: 25 | E40: 12 | F40: =VLOOKUP(E40,$B$29:$C$124,2) -> 0.755 | G40: =INT(((ROW(G12)-1)/75)+1) -> 1 | H40: =AVERAGEIF($G$29:$G$3417, J39, $F$29:$F$3387) -> 17.543333 | J40: 13
B41: =B40+D40 -> 301 | C41: 9.335 | D41: 25 | E41: 13 | F41: =VLOOKUP(E41,$B$29:$C$124,2) -> 0.755 | G41: =INT(((ROW(G13)-1)/75)+1) -> 1 | H41: =AVERAGEIF($G$29:$G$3417, J40, $F$29:$F$3387) -> 19.942 | J41: 14
... B52: =B51+D51 -> 576 | C52: 16.604 | D52: 25 | E52: 24 | F52: =VLOOKUP(E52,$B$29:$C$124,2) -> 0.755 | G52: =INT(((ROW(G24)-1)/75)+1) -> 1 | H52: =AVERAGEIF($G$29:$G$3417, J51, $F$29:$F$3387) -> 27.935 | J52: 25
B53: =B52+D52 -> 601 | C53: 25.088 | D53: 25 | E53: 25 | F53: =VLOOKUP(E53,$B$29:$C$124,2) -> 0.755 | G53: =INT(((ROW(G25)-1)/75)+1) -> 1 | H53: =AVERAGEIF($G$29:$G$3417, J52, $F$29:$F$3387) -> 27.887333
B54: =B53+D53 -> 626 | C54: 19.854 | D54: 25 | E54: 26 | F54: =VLOOKUP(E54,$B$29:$C$124,2) -> 2.264 | G54: =INT(((ROW(G26)-1)/75)+1) -> 1
B55: =B54+D54 -> 651 | C55: 26.747 | D55: 25 | E55: 27 | F55: =VLOOKUP(E55,$B$29:$C$124,2) -> 2.264 | G55: =INT(((ROW(G27)-1)/75)+1) -> 1
B56: =B55+D55 -> 676 | C56: 24.257 | D56: 25 | E56: 28 | F56: =VLOOKUP(E56,$B$29:$C$124,2) -> 2.264 | G56: =INT(((ROW(G28)-1)/75)+1) -> 1
B57: =B56+D56 -> 701 | C57: 13.669 | D57: 25 | E57: 29 | F57: =VLOOKUP(E57,$B$29:$C$124,2) -> 2.264 | G57: =INT(((ROW(G29)-1)/75)+1) -> 1
B58: =B57+D57 -> 726 | C58: 18.129 | D58: 25 | E58: 30 | F58: =VLOOKUP(E58,$B$29:$C$124,2) -> 2.264 | G58: =INT(((ROW(G30)-1)/75)+1) -> 1
B59: =B58+D58 -> 751 | C59: 24.198 | D59: 25 | E59: 31 | F59: =VLOOKUP(E59,$B$29:$C$124,2) -> 2.264 | G59: =INT(((ROW(G31)-1)/75)+1) -> 1
...

Sheet Standardized - 2020
A1: Year | B1: Standardized Cell Number | C1: Under42 | D1: WAS27 | E1: WAS03 | F1: WAS21 | G1: WAS36 | H1: WAS49 | I1: GT-1 | J1: GT-3 | K1: GT-4 | L1: WAS61 | M1: AboveP1 | N1: WAS51 | O1: WAS50 | P1: WAS42 | Q1: WAS01 | R1: WAS04 | S1: WAS63 | T1: WAS64 | U1: WAS48 | V1: WAS57 | W1: WAS65 | Y1: Standardized Ring | Z1: DF-Cliff | AA1: DF-Soil | AB1: ES-Cliff | AC1: ES-Soil | AE1: Species | AF1: Site | AG1: Average LD | AH1: SD | AI1: SE
A2: 2020 | B2: 1 | C2: 3.2647308 | D2: 0.755 | E2: 1.3910588 | F2: 1.509 | G2: 2.7708889 | H2: 3.112 | I2: 3.4755962 | J2: 3.088814 | K2: 2.0397547 | L2: 2.0609545 | M2: 3.5471814 | N2: 4.890717 | O2: 0.78457143 | P2: 3.0588974 | Q2: 1.5093333 | R2: 5.148 | S2: 4.1615 | T2: 1.5960175 | U2: 2.5411582 | V2: 4.1182174 | W2: 5.6146275 | Y2: 1 | Z2: =AVERAGE(C2:G2) -> 1.9381357 | AA2: =AVERAGE(H2:L2) -> 2.7554239 | AB2: =AVERAGE(M2:R2) -> 3.1564501 | AC2: =AVERAGE(S2:W2) -> 3.6063041 | AE2: Spruce | AF2: Soil | AG2: =AVERAGE(S2:W26) -> 21.870989 | AH2: =STDEV(S2:W26) -> 9.4906611 | AI2: =AH2/SQRT(125) -> 0.84887053
A3: 2020 | B3: 2 | C3: 4.8813269 | D3: 0.755 | E3: 1.5259608 | F3: 2.07525 | G3: 4.6999565 | H3: 3.848 | I3: 4.4912308 | J3: 3.8262209 | K3: 3.6332708 | L3: 4.5967784 | M3: 4.40382 | N3: 5.8120295 | O3: 1.308 | P3: 4.0945385 | Q3: 1.5093333 | R3: 4.4400714 | S3: 5.4815342 | T3: 2.950614 | U3: 5.9737627 | V3: 3.3436957 | W3: 10.163706 | Y3: 2 | Z3: =AVERAGE(C3:G3) -> 2.7874988 | AA3: =AVERAGE(H3:L3) -> 4.0791002 | AB3: =AVERAGE(M3:R3) -> 3.5946321 | AC3: =AVERAGE(S3:W3) -> 5.5826625 | AE3: Spruce | AF3: Cliff | AG3: =AVERAGE($M$2:$Q$26) -> 16.197398 | AH3: =STDEV($M$2:$Q$26) -> 8.2628876 | AI3: =AH3/SQRT(125) -> 0.73905513
A4: 2020 | B4: 3 | C4: 5.4381904 | D4: 0.755 | E4: 2.4243922 | F4: 3.20775 | G4: 4.9895749 | H4: 2.264 | I4: 4.1656538 | J4: 3.5279612 | K4: 4.6975708 | L4: 4.8856648 | M4: 6.8790943 | N4: 8.265936 | O4: 2.6279524 | P4: 4.6183942 | Q4: 1.5092917 | R4: 5.6084762 | S4: 8.481911 | T4: 4.8513158 | U4: 9.810452 | V4: 6.1912174 | W4: 11.593196 | Y4: 3 | Z4: =AVERAGE(C4:G4) -> 3.3629815 | AA4: =AVERAGE(H4:L4) -> 3.9081701 | AB4: =AVERAGE(M4:R4) -> 4.9181908 | AC4: =AVERAGE(S4:W4) -> 8.1856184 | AE4: Douglas Fir | AF4: Soil | AG4: =AVERAGE($H$2:$L$26) -> 19.332604 | AH4: =STDEV($H$2:$L$26) -> 10.84836 | AI4: =AH4/SQRT(125) -> 0.97030686
A5: 2020 | B5: 4 | C5: 5.2595538 | D5: 1.2531071 | E5: 2.3380196 | F5: 4.6000833 | G5: 4.6705459 | H5: 4.16975 | I5: 4.9358205 | J5: 4.8204574 | K5: 4.9807659 | L5: 3.9686136 | M5: 6.4409753 | N5: 9.605178 | O5: 3.9240476 | P5: 5.2719808 | Q5: 1.50925 | R5: 6.1275714 | S5: 10.826062 | T5: 7.1987018 | U5: 10.566559 | V5: 7.4841957 | W5: 12.343098 | Y5: 4 | Z5: =AVERAGE(C5:G5) -> 3.624262 | AA5: =AVERAGE(H5:L5) -> 4.5750815 | AB5: =AVERAGE(M5:R5) -> 5.4798339 | AC5: =AVERAGE(S5:W5) -> 9.6837233 | AE5: Douglas Fir | AF5: Cliff | AG5: =AVERAGE($C$2:$G$26) -> 15.056306 | AH5: =STDEV($C$2:$G$26) -> 8.4336118 | AI5: =AH5/SQRT(125) -> 0.75432517
A6: 2020 | B6: 5 | C6: 5.3153231 | D6: 1.91725 | E6: 3.2035098 | F6: 5.29625 | G6: 6.2601691 | H6: 4.15125 | I6: 4.5872436 | J6: 6.2074961 | K6: 7.0396451 | L6: 4.2649205 | M6: 6.5603657 | N6: 11.185418 | O6: 5.326381 | P6: 6.6783365 | Q6: 1.50925 | R6: 6.0776667 | S6: 12.648342 | T6: 5.773614 | U6: 10.648181 | V6: 6.2020217 | W6: 15.056549 | Y6: 5 | Z6: =AVERAGE(C6:G6) -> 4.3985004 | AA6: =AVERAGE(H6:L6) -> 5.250111 | AB6: =AVERAGE(M6:R6) -> 6.2229029 | AC6: =AVERAGE(S6:W6) -> 10.065742
A7: 2020 | B7: 6 | C7: 5.7944923 | D7: 1.91725 | E7: 5.6407059 | F7: 10.18875 | G7: 7.7831787 | H7: 5.10475 | I7: 6.1818974 | J7: 7.7591085 | K7: 6.87444 | L7: 6.2407557 | M7: 7.3828621 | N7: 12.436384 | O7: 6.1096905 | P7: 9.4154615 | Q7: 3.0635 | R7: 7.2092857 | S7: 15.709459 | T7: 9.299 | U7: 15.47061 | V7: 7.547 | W7: 15.815353 | Y7: 6 | Z7: =AVERAGE(C7:G7) -> 6.2648754 | AA7: =AVERAGE(H7:L7) -> 6.4321903 | AB7: =AVERAGE(M7:R7) -> 7.602864 | AC7: =AVERAGE(S7:W7) -> 12.768284
A8: 2020 | B8: 7 | C8: 6.6818154 | D8: 1.91725 | E8: 8.4564216 | F8: 12.138417 | G8: 10.52244 | H8: 6.415 | I8: 8.1357051 | J8: 11.840992 | K8: 7.575629 | L8: 8.8301847 | M8: 9.1072917 | N8: 13.018264 | O8: 7.2430833 | P8: 11.559808 | Q8: 3.0635 | R8: 7.2283333 | S8: 19.678055 | T8: 15.146561 | U8: 18.770412 | V8: 7.9243478 | W8: 20.490353 | Y8: 7 | Z8: =AVERAGE(C8:G8) -> 7.9432686 | AA8: =AVERAGE(H8:L8) -> 8.5595022 | AB8: =AVERAGE(M8:R8) -> 8.5367134 | AC8: =AVERAGE(S8:W8) -> 16.401946
A9: 2020 | B9: 8 | C9: 7.5784 | D9: 4.2973214 | E9: 11.769333 | F9: 16.03775 | G9: 12.808691 | H9: 6.80425 | I9: 10.597769 | J9: 13.416938 | K9: 7.4265624 | L9: 11.845861 | M9: 10.732842 | N9: 13.258166 | O9: 7.9901429 | P9: 13.809154 | Q9: 7.386375 | R9: 7.9843333 | S9: 19.507123 | T9: 16.267386 | U9: 22.614237 | V9: 11.025717 | W9: 19.771882 | Y9: 8 | Z9: =AVERAGE(C9:G9) -> 10.498299 | AA9: =AVERAGE(H9:L9) -> 10.018276 | AB9: =AVERAGE(M9:R9) -> 10.193502 | AC9: =AVERAGE(S9:W9) -> 17.837269
A10: 2020 | B10: 9 | C10: 8.8866538 | D10: 4.694 | E10: 11.487392 | F10: 19.061583 | G10: 12.81714 | H10: 8.13 | I10: 11.856269 | J10: 18.076775 | K10: 13.187843 | L10: 16.610094 | M10: 11.958044 | N10: 13.896308 | O10: 10.249357 | P10: 14.418471 | Q10: 11.70925 | R10: 11.147889 | S10: 21.716582 | T10: 18.961509 | U10: 26.242407 | V10: 12.436391 | W10: 19.498275 | Y10: 9 | Z10: =AVERAGE(C10:G10) -> 11.389354 | AA10: =AVERAGE(H10:L10) -> 13.572196 | AB10: =AVERAGE(M10:R10) -> 12.229887 | AC10: =AVERAGE(S10:W10) -> 19.771033
A11: 2020 | B11: 10 | C11: 11.331292 | D11: 4.694 | E11: 13.359529 | F11: 20.5735 | G11: 16.526014 | H11: 12.086 | I11: 12.619 | J11: 26.45107 | K11: 11.931252 | L11: 18.69667 | M11: 13.239512 | N11: 14.950681 | O11: 14.674036 | P11: 17.851962 | Q11: 11.70925 | R11: 13.769048 | S11: 25.117171 | T11: 21.316509 | U11: 27.788294 | V11: 11.796761 | W11: 24.539333 | Y11: 10 | Z11: =AVERAGE(C11:G11) -> 13.296867 | AA11: =AVERAGE(H11:L11) -> 16.356798 | AB11: =AVERAGE(M11:R11) -> 14.365748 | AC11: =AVERAGE(S11:W11) -> 22.111614
A12: 2020 | B12: 11 | C12: 13.603515 | D12: 6.6304571 | E12: 14.273059 | F12: 21.70775 | G12: 20.893609 | H12: 12.482 | I12: 15.509667 | J12: 30.089574 | K12: 16.431737 | L12: 22.552281 | M12: 15.114978 | N12: 14.789158 | O12: 21.183381 | P12: 18.624298 | Q12: 16.63925 | R12: 16.537286 | S12: 27.867808 | T12: 25.593842 | U12: 28.228073 | V12: 22.518435 | W12: 24.28198 | Y12: 11 | Z12: =AVERAGE(C12:G12) -> 15.421678 | AA12: =AVERAGE(H12:L12) -> 19.413052 | AB12: =AVERAGE(M12:R12) -> 17.148059 | AC12: =AVERAGE(S12:W12) -> 25.698028
A13: 2020 | B13: 12 | C13: 16.094785 | D13: 11.4716 | E13: 14.192343 | F13: 21.401417 | G13: 19.228749 | H13: 18.13225 | I13: 17.883513 | J13: 31.109078 | K13: 21.149079 | L13: 22.448557 | M13: 16.658833 | N13: 16.552912 | O13: 22.732036 | P13: 18.353635 | Q13: 16.63925 | R13: 20.771667 | S13: 24.506747 | T13: 29.219684 | U13: 24.821412 | V13: 22.480391 | W13: 23.113235 | Y13: 12 | Z13: =AVERAGE(C13:G13) -> 16.477779 | AA13: =AVERAGE(H13:L13) -> 22.144495 | AB13: =AVERAGE(M13:R13) -> 18.618055 | AC13: =AVERAGE(S13:W13) -> 24.828294
A14: 2020 | B14: 13 | C14: 17.3715 | D14: 11.4716 | E14: 15.6785 | F14: 20.78875 | G14: 18.748135 | H14: 22.4755 | I14: 17.2925 | J14: 32.201109 | K14: 21.882094 | L14: 24.546065 | M14: 16.931396 | N14: 16.74234 | O14: 22.0385 | P14: 20.296125 | Q14: 17.96725 | R14: 24.052333 | S14: 27.443322 | T14: 30.87086 | U14: 25.105073 | V14: 20.063 | W14: 26.890314 | Y14: 13 | Z14: =AVERAGE(C14:G14) -> 16.811697 | AA14: =AVERAGE(H14:L14) -> 23.679454 | AB14: =AVERAGE(M14:R14) -> 19.671324 | AC14: =AVERAGE(S14:W14) -> 26.074514
A15: 2020 | B15: 14 | C15: 16.528723 | D15: 11.4716 | E15: 15.299804 | F15: 21.92875 | G15: 15.487348 | H15: 24.18125 | I15: 20.160026 | J15: 34.424612 | K15: 25.92899 | L15: 25.558278 | M15: 17.427065 | N15: 19.528886 | O15: 22.110774 | P15: 21.224558 | Q15: 19.29525 | R15: 25.868794 | S15: 27.89726 | T15: 32.213509 | U15: 29.53939 | V15: 18.858109 | W15: 27.948059 | Y15: 14 | Z15: =AVERAGE(C15:G15) -> 16.143245 | AA15: =AVERAGE(H15:L15) -> 26.050631 | AB15: =AVERAGE(M15:R15) -> 20.909221 | AC15: =AVERAGE(S15:W15) -> 27.291265
A16: 2020 | B16: 15 | C16: 20.294092 | D16: 15.237314 | E16: 18.62051 | F16: 22.49875 | G16: 18.379623 | H16: 24.8475 | I16: 21.743718 | J16: 33.865628 | K16: 28.115655 | L16: 25.946324 | M16: 19.265521 | N16: 20.974399 | O16: 20.534952 | P16: 20.553596 | Q16: 19.29525 | R16: 28.832857 | S16: 27.556164 | T16: 30.323684 | U16: 28.075147 | V16: 17.313978 | W16: 31.089843 | Y16: 15 | Z16: =AVERAGE(C16:G16) -> 19.006058 | AA16: =AVERAGE(H16:L16) -> 26.903765 | AB16: =AVERAGE(M16:R16) -> 21.576096 | AC16: =AVERAGE(S16:W16) -> 26.871763
A17: 2020 | B17: 16 | C17: 23.570385 | D17: 16.7436 | E17: 19.856539 | F17: 27.024 | G17: 22.240471 | H17: 27.61725 | I17: 23.694949 | J17: 37.201333 | K17: 29.007861 | L17: 30.75033 | M17: 18.62883 | N17: 25.290697 | O17: 21.190429 | P17: 20.494712 | Q17: 19.64475 | R17: 30.69646 | S17: 24.825842 | T17: 34.895175 | U17: 30.374407 | V17: 23.698 | W17: 30.234784 | Y17: 16 | Z17: =AVERAGE(C17:G17) -> 21.886999 | AA17: =AVERAGE(H17:L17) -> 29.654345 | AB17: =AVERAGE(M17:R17) -> 22.657646 | AC17: =AVERAGE(S17:W17) -> 28.805642
... A26: 2020 | B26: 25 | C26: 20.753762 | D26: 21.0402 | E26: 19.938235 | F26: 21.139 | G26: 23.320971 | H26: 21.27725 | I26: 29.974474 | J26: 29.834636 | K26: 27.761756 | L26: 32.340415 | M26: 14.638628 | N26: 19.981887 | O26: 31.905571 | P26: 36.983997 | Q26: 22.52525 | R26: 34.369333 | S26: 29.588829 | T26: 34.146982 | U26: 25.764915 | V26: 34.970913 | W26: 36.931686 | Y26: 25 | Z26: =AVERAGE(C26:G26) -> 21.238434 | AA26: =AVERAGE(H26:L26) -> 28.237706 | AB26: =AVERAGE(M26:R26) -> 26.734111 | AC26: =AVERAGE(S26:W26) -> 32.280665
B28: Helper Column | D28: Repeat Times | E28: Helper Column | F28: Product | H28: Final | J28: 1
B29: 1 | C29: 3.774 | D29: 25 | E29: 1 | F29: =VLOOKUP(E29,$B$29:$C$135,2) -> 3.774 | G29: =INT(((ROW(G1)-1)/46)+1) -> 1 | H29: =AVERAGEIF($G$29:$G$3417, J28, $F$29:$F$3387) -> 4.1182174 | J29: 2
B30: =B29+D29 -> 26 | C30: 4.528 | D30: 25 | E30: 2 | F30: =VLOOKUP(E30,$B$29:$C$135,2) -> 3.774 | G30: =INT(((ROW(G2)-1)/46)+1) -> 1 | H30: =AVERAGEIF($G$29:$G$3417, J29, $F$29:$F$3387) -> 3.3436957 | J30: 3
B31: =B30+D30 -> 51 | C31: 3.375 | D31: 25 | E31: 3 | F31: =VLOOKUP(E31,$B$29:$C$135,2) -> 3.774 | G31: =INT(((ROW(G3)-1)/46)+1) -> 1 | H31: =AVERAGEIF($G$29:$G$3417, J30, $F$29:$F$3387) -> 6.1912174 | J31: 4
B32: =B31+D31 -> 76 | C32: 3.019 | D32: 25 | E32: 4 | F32: =VLOOKUP(E32,$B$29:$C$135,2) -> 3.774 | G32: =INT(((ROW(G4)-1)/46)+1) -> 1 | H32: =AVERAGEIF($G$29:$G$3417, J31, $F$29:$F$3387) -> 7.4841957 | J32: 5
B33: =B32+D32 -> 101 | C33: 6.038 | D33: 25 | E33: 5 | F33: =VLOOKUP(E33,$B$29:$C$135,2) -> 3.774 | G33: =INT(((ROW(G5)-1)/46)+1) -> 1 | H33: =AVERAGEIF($G$29:$G$3417, J32, $F$29:$F$3387) -> 6.2020217 | J33: 6
B34: =B33+D33 -> 126 | C34: 8.438 | D34: 25 | E34: 6 | F34: =VLOOKUP(E34,$B$29:$C$135,2) -> 3.774 | G34: =INT(((ROW(G6)-1)/46)+1) -> 1 | H34: =AVERAGEIF($G$29:$G$3417, J33, $F$29:$F$3387) -> 7.547 | J34: 7
B35: =B34+D34 -> 151 | C35: 7.547 | D35: 25 | E35: 7 | F35: =VLOOKUP(E35,$B$29:$C$135,2) -> 3.774 | G35: =INT(((ROW(G7)-1)/46)+1) -> 1 | H35: =AVERAGEIF($G$29:$G$3417, J34, $F$29:$F$3387) -> 7.9243478 | J35: 8
B36: =B35+D35 -> 176 | C36: 6.038 | D36: 25 | E36: 8 | F36: =VLOOKUP(E36,$B$29:$C$135,2) -> 3.774 | G36: =INT(((ROW(G8)-1)/46)+1) -> 1 | H36: =AVERAGEIF($G$29:$G$3417, J35, $F$29:$F$3387) -> 11.025717 | J36: 9
B37: =B36+D36 -> 201 | C37: 6.038 | D37: 25 | E37: 9 | F37: =VLOOKUP(E37,$B$29:$C$135,2) -> 3.774 | G37: =INT(((ROW(G9)-1)/46)+1) -> 1 | H37: =AVERAGEIF($G$29:$G$3417, J36, $F$29:$F$3387) -> 12.436391 | J37: 10
B38: =B37+D37 -> 226 | C38: 7.547 | D38: 25 | E38: 10 | F38: =VLOOKUP(E38,$B$29:$C$135,2) -> 3.774 | G38: =INT(((ROW(G10)-1)/46)+1) -> 1 | H38: =AVERAGEIF($G$29:$G$3417, J37, $F$29:$F$3387) -> 11.796761 | J38: 11
B39: =B38+D38 -> 251 | C39: 7.547 | D39: 25 | E39: 11 | F39: =VLOOKUP(E39,$B$29:$C$135,2) -> 3.774 | G39: =INT(((ROW(G11)-1)/46)+1) -> 1 | H39: =AVERAGEIF($G$29:$G$3417, J38, $F$29:$F$3387) -> 22.518435 | J39: 12
B40: =B39+D39 -> 276 | C40: 7.547 | D40: 25 | E40: 12 | F40: =VLOOKUP(E40,$B$29:$C$135,2) -> 3.774 | G40: =INT(((ROW(G12)-1)/46)+1) -> 1 | H40: =AVERAGEIF($G$29:$G$3417, J39, $F$29:$F$3387) -> 22.480391 | J40: 13
B41: =B40+D40 -> 301 | C41: 8.336 | D41: 25 | E41: 13 | F41: =VLOOKUP(E41,$B$29:$C$135,2) -> 3.774 | G41: =INT(((ROW(G13)-1)/46)+1) -> 1 | H41: =AVERAGEIF($G$29:$G$3417, J40, $F$29:$F$3387) -> 20.063 | J41: 14
... B52: =B51+D51 -> 576 | C52: 20.503 | D52: 25 | E52: 24 | F52: =VLOOKUP(E52,$B$29:$C$135,2) -> 3.774 | G52: =INT(((ROW(G24)-1)/46)+1) -> 1 | H52: =AVERAGEIF($G$29:$G$3417, J51, $F$29:$F$3387) -> 34.635391 | J52: 25
B53: =B52+D52 -> 601 | C53: 25.008 | D53: 25 | E53: 25 | F53: =VLOOKUP(E53,$B$29:$C$135,2) -> 3.774 | G53: =INT(((ROW(G25)-1)/46)+1) -> 1 | H53: =AVERAGEIF($G$29:$G$3417, J52, $F$29:$F$3387) -> 34.970913
B54: =B53+D53 -> 626 | C54: 10.593 | D54: 25 | E54: 26 | F54: =VLOOKUP(E54,$B$29:$C$135,2) -> 4.528 | G54: =INT(((ROW(G26)-1)/46)+1) -> 1
B55: =B54+D54 -> 651 | C55: 18.363 | D55: 25 | E55: 27 | F55: =VLOOKUP(E55,$B$29:$C$135,2) -> 4.528 | G55: =INT(((ROW(G27)-1)/46)+1) -> 1
B56: =B55+D55 -> 676 | C56: 18.254 | D56: 25 | E56: 28 | F56: =VLOOKUP(E56,$B$29:$C$135,2) -> 4.528 | G56: =INT(((ROW(G28)-1)/46)+1) -> 1
B57: =B56+D56 -> 701 | C57: 25.671 | D57: 25 | E57: 29 | F57: =VLOOKUP(E57,$B$29:$C$135,2) -> 4.528 | G57: =INT(((ROW(G29)-1)/46)+1) -> 1
B58: =B57+D57 -> 726 | C58: 24.163 | D58: 25 | E58: 30 | F58: =VLOOKUP(E58,$B$29:$C$135,2) -> 4.528 | G58: =INT(((ROW(G30)-1)/46)+1) -> 1
B59: =B58+D58 -> 751 | C59: 18.883 | D59: 25 | E59: 31 | F59: =VLOOKUP(E59,$B$29:$C$135,2) -> 4.528 | G59: =INT(((ROW(G31)-1)/46)+1) -> 1
...

Sheet Standardized - ALL
A1: Standardized Ring | B1: DF-Cliff-2018 | C1: DF-Cliff-2019 | D1: DF-Cliff-2020 | E1: Standardized Ring | F1: DF-Soil-2018 | G1: DF-Soil-2019 | H1: DF-Soil-2020 | I1: Standardized Ring | J1: ES-Cliff-2018 | K1: ES-Cliff-2019 | L1: ES-Cliff-2020 | M1: Standardized Ring | N1: ES-Soil-2018 | O1: ES-Soil-2019 | P1: ES-Soil-2020 | R1: Species | S1: Site | T1: Average LD | U1: SD | V1: SE | W1: YEAR
A2: 1 | B2: 2.4519204 | C2: 2.6071831 | D2: 1.9381357 | E2: 1 | F2: 3.9208884 | G2: 3.9525055 | H2: 2.7554239 | I2: 1 | J2: 3.0861715 | K2: 3.026544 | L2: 3.1564501 | M2: 1 | N2: 3.2937314 | O2: 3.3410916 | P2: 3.6063041 | R2: Spruce | S2: Soil | T2: 23.025567 | U2: 9.849947 | V2: 0.88100605 | W2: 2018
A3: 2 | B3: 3.3957911 | C3: 3.0620116 | D3: 2.7874988 | E3: 2 | F3: 4.9268313 | G3: 5.9565448 | H3: 4.0791002 | I3: 2 | J3: 3.6375144 | K3: 3.9281733 | L3: 3.5946321 | M3: 2 | N3: 5.6669636 | O3: 6.6046816 | P3: 5.5826625 | R3: Spruce | S3: Cliff | T3: 15.341354 | U3: 7.5335678 | V3: 0.67382279 | W3: 2018
